Workbook
Name ORB_V1_sh1_111110011553438: 'Traffic Data'!$B$8
Name ORB_V1_sh1_111110031041880: 'Traffic Data'!$B$9
Name ORB_V1_sh1_111110115509284: 'Traffic Data'!$B$7
Name ORB_V1_sh2_111110035412386: 'Conversion Data'!$B$7
Name ORB_V1_sh2_111111010206845: 'Traffic Data'!$BA$6
Name ORB_V1_sh2_111111010251999: 'Traffic Data'!$B$11
Name ORB_V1_sh2_111111125530097: 'Traffic Data'!$B$10
Name ORB_V1_sh2_111111125854440: 'Traffic Data'!$AR$6
Name ORB_V1_sh4_111111110644720: 'Unique Visitors'!$B$7
Name ORB_V1_sh4_111111111526602: 'Unique Visitors'!$B$7
Name ORB_V1_sh4_111111112504747: 'Unique Visitors'!$B$7
Name ORB_V1_sh4_111202043031889: 'Traffic Data'!$B$12
Name ORB_V1_sh4_111202043940709: 'Traffic Data'!$BS$6
Name ORB_V1_sh4_111202044006439: 'Traffic Data'!$B$13
Name ORB_V1_sh4_111202044258363: 'Traffic Data'!$BW$6
Name ORB_V1_sh4_111202044343132: 'Traffic Data'!$B$14
Name ORB_V1_sh4_111202044555251: 'Traffic Data'!$CA$6
Name ORB_V1_sh4_111202044604236: 'Traffic Data'!$B$15
Name ORB_V1_sh4_111202044808508: 'Traffic Data'!$CE$6
Name ORB_V1_sh4_111202044821362: 'Traffic Data'!$B$16
Name ORB_V1_sh4_111202045030391: 'Traffic Data'!$CI$6
Name ORB_V1_sh4_111202045046333: 'Traffic Data'!$B$17
Name ORB_V1_sh5_111208043217057: 'Traffic Data'!$K$6
Name ORB_V1_sh5_111208043342531: 'Traffic Data'!$U$6
Name ORB_V1_sh5_111208043420125: 'Traffic Data'!$AD$6
Name ORB_V1_sh5_111208050834201: 'Traffic Data'!$BO$6
Name ORB_V1_sh6_111209121735557: 'Conversion Data'!$K$6
Name ORB_V1_sh6_111213023335064: 'Conversion Data'!$AF$6
Name ORB_V1_sh6_111213023515872: 'Conversion Data'!$B$7
Name ORB_V1_sh6_111213024055110: 'Conversion Data'!$AQ$6
Name ORB_V1_sh6_111213024109572: 'Conversion Data'!$B$7
Name ORB_V1_sh6_111213025056932: 'Conversion Data'!$BB$6
Name ORB_V1_sh6_111213025217975: 'Conversion Data'!$B$7
Name ORB_V1_sh6_111213045203402: 'Organic Keywords'!$D$1
Name ORB_V1_sh7_111208043622337: 'Unique Visitors'!$K$6
Name ORB_V1_sh7_111208043824188: 'Unique Visitors'!$U$6
Name ORB_V1_sh7_111208045058606: 'Unique Visitors'!$Z$6
Name ORB_V1_shORB_SHEETCODENAME_111110115218432_111110115218432: 'Traffic Data'!$B$1
Name ORB_V1_shORB_SHEETCODENAME_111110120324455_111111110601421: 'Unique Visitors'!$B$1
Name ORB_V1_shORB_SHEETCODENAME_111110120324470_111110035230576: 'Conversion Data'!$B$1
Name ORB_V1_shORB_SHEETCODENAME_111213034151402_111213034255533: 'Organic Keywords'!$B$1

Sheet Conversion Summary
A1: 11 | B1: =A1-1 -> 10
E3: Conversion Events | F3: This Period | G3: Last Period | I3: % Change | J3: YTD
E4: ='Conversion Data'!$L$6 -> Site: Revenue | F4: =SUMIF('Conversion Data'!$F$7:$F$371,$A$1,'Conversion Data'!$L$7:$L$371) -> 0 | G4: =SUMIF('Conversion Data'!$F$7:$F$371,$B$1,'Conversion Data'!$L$7:$L$371) -> 0 | H4: =IF(I4="-","",IF(I4>0,"p","q")) | I4: =IF(G4<>0,(F4-G4)/G4,"-") -> - | J4: =SUM('Conversion Data'!$L$7:$L$371) -> 22518699
E5: ='Conversion Data'!$M$6 -> Site: Orders | F5: =SUMIF('Conversion Data'!$F$7:$F$371,$A$1,'Conversion Data'!$M$7:$M$371) -> 0 | G5: =SUMIF('Conversion Data'!$F$7:$F$371,$B$1,'Conversion Data'!$M$7:$M$371) -> 0 | H5: =IF(I5="-","",IF(I5>0,"p","q")) | I5: =IF(G5<>0,(F5-G5)/G5,"-") -> - | J5: =SUM('Conversion Data'!$M$7:$M$371) -> 133011
E6: ='Conversion Data'!O6 -> Shop: Checkouts | F6: =SUMIF('Conversion Data'!$F$7:$F$371,$A$1,'Conversion Data'!$O$7:$O$371) -> 0 | G6: =SUMIF('Conversion Data'!$F$7:$F$371,$B$1,'Conversion Data'!$O$7:$O$371) -> 0 | H6: =IF(I6="-","",IF(I6>0,"p","q")) | I6: =IF(G6<>0,(F6-G6)/G6,"-") -> - | J6: =SUM('Conversion Data'!$O$7:$O$371) -> 283773
E7: ='Conversion Data'!P6 -> Shop: Carts | F7: =SUMIF('Conversion Data'!$F$7:$F$371,$A$1,'Conversion Data'!$P$7:$P$371) -> 0 | G7: =SUMIF('Conversion Data'!$F$7:$F$371,$B$1,'Conversion Data'!$P$7:$P$371) -> 0 | H7: =IF(I7="-","",IF(I7>0,"p","q")) | I7: =IF(G7<>0,(F7-G7)/G7,"-") -> - | J7: =SUM('Conversion Data'!$P$7:$P$371) -> 332706
E8: ='Conversion Data'!Q6 -> Shop: Cart Additions | F8: =SUMIF('Conversion Data'!$F$7:$F$371,$A$1,'Conversion Data'!$Q$7:$Q$371) -> 0 | G8: =SUMIF('Conversion Data'!$F$7:$F$371,$B$1,'Conversion Data'!$Q$7:$Q$371) -> 0 | H8: =IF(I8="-","",IF(I8>0,"p","q")) | I8: =IF(G8<>0,(F8-G8)/G8,"-") -> - | J8: =SUM('Conversion Data'!$Q$7:$Q$371) -> 859123
E9: ='Conversion Data'!R6 -> Shop: Cart Removals | F9: =SUMIF('Conversion Data'!$F$7:$F$371,$A$1,'Conversion Data'!$R$7:$R$371) -> 0 | G9: =SUMIF('Conversion Data'!$F$7:$F$371,$B$1,'Conversion Data'!$R$7:$R$371) -> 0 | H9: =IF(I9="-","",IF(I9>0,"p","q")) | I9: =IF(G9<>0,(F9-G9)/G9,"-") -> - | J9: =SUM('Conversion Data'!$R$7:$R$371) -> 94782
E10: ='Conversion Data'!S6 -> 0 | F10: =SUMIF('Conversion Data'!$F$7:$F$371,$A$1,'Conversion Data'!$S$7:$S$371) -> 0 | G10: =SUMIF('Conversion Data'!$F$7:$F$371,$B$1,'Conversion Data'!$S$7:$S$371) -> 0 | H10: =IF(I10="-","",IF(I10>0,"p","q")) | I10: =IF(G10<>0,(F10-G10)/G10,"-") -> - | J10: =SUM('Conversion Data'!$S$7:$S$371) -> 0
E12: Site Section Visits | F12: This Period | G12: Last Period | I12: % Change | J12: YTD
E13: =Config!B8 -> cpc.ca: shop > business | F13: =SUMIF('Traffic Data'!$F$7:$F$371,'Conversion Summary'!$A$1,'Traffic Data'!$V$7:$V$371) -> 0 | G13: =SUMIF('Traffic Data'!$F$7:$F$371,'Conversion Summary'!$B$1,'Traffic Data'!$V$7:$W$371) -> 0 | H13: =IF(I13="-","",IF(I13>0,"p","q")) | I13: =IF(G13<>0,(F13-G13)/G13,"-") -> - | J13: =SUM('Traffic Data'!$V$7:$V$371) -> 237935
E14: =Config!B9 -> cpc.ca: shop > commercial | F14: =SUMIF('Traffic Data'!$F$7:$F$371,'Conversion Summary'!$A$1,'Traffic Data'!$AE$7:$AE$371) -> 0 | G14: =SUMIF('Traffic Data'!$F$7:$F$371,'Conversion Summary'!$B$1,'Traffic Data'!$AE$7:$AE$371) -> 0 | H14: =IF(I14="-","",IF(I14>0,"p","q")) | I14: =IF(G14<>0,(F14-G14)/G14,"-") -> - | J14: =SUM('Traffic Data'!$AE$7:$AE$371) -> 144900
E15: =Config!B10 -> cpc.ca: shop > personal | F15: =SUMIF('Traffic Data'!$F$7:$F$371,'Conversion Summary'!$A$1,'Traffic Data'!$AS$7:$AS$371) -> 0 | G15: =SUMIF('Traffic Data'!$F$7:$F$371,'Conversion Summary'!$B$1,'Traffic Data'!$AS$7:$AS$371) -> 0 | H15: =IF(I15="-","",IF(I15>0,"p","q")) | I15: =IF(G15<>0,(F15-G15)/G15,"-") -> - | J15: =SUM('Traffic Data'!$AS$7:$AS$371) -> 1811391
E16: =Config!B11 -> cpc.ca: shop > collecting | F16: =SUMIF('Traffic Data'!$F$7:$F$371,'Conversion Summary'!$A$1,'Traffic Data'!$BB$7:$BB$371) -> 0 | G16: =SUMIF('Traffic Data'!$F$7:$F$371,'Conversion Summary'!$B$1,'Traffic Data'!$BB$7:$BB$371) -> 0 | H16: =IF(I16="-","",IF(I16>0,"p","q")) | I16: =IF(G16<>0,(F16-G16)/G16,"-") -> - | J16: =SUM('Traffic Data'!$BB$7:$BB$371) -> 646478

Sheet Fallout Summary
A1: 1 | B1: 2 | C1: 3 | D1: 4 | E1: 5 | F1: 6 | G1: 7 | H1: 8
C2: Fallout Report Data - All Stores
B3: Year | C3: Month | D3: Step1 | E3: Step2 | F3: Step3 | G3: Step4 | H3: Complete
A4: =C4 -> 40452 | B4: 2011 | C4: ='Traffic Data'!BS7 -> 40452 | D4: =SUMIF('Traffic Data'!$F$7:$F$371,$A4,'Traffic Data'!$BT$7:$BT$371) -> 5066 | E4: =SUMIF('Traffic Data'!$F$7:$F$371,$A4,'Traffic Data'!$BX$7:$BX$371) -> 4930 | F4: =SUMIF('Traffic Data'!$F$7:$F$371,$A4,'Traffic Data'!$CB$7:$CB$371) -> 4829 | G4: =SUMIF('Traffic Data'!$F$7:$F$371,$A4,'Traffic Data'!$CF$7:$CF$371) -> 4442 | H4: =SUMIF('Traffic Data'!$F$7:$F$371,$A4,'Traffic Data'!$CJ$7:$CJ$371) -> 4163 | I4: =(H4-G4)/G4 -> -0.062809545
A5: =C5 -> 40483 | B5: 2011 | C5: ='Traffic Data'!BS8 -> 40483 | D5: =SUMIF('Traffic Data'!$F$7:$F$371,$A5,'Traffic Data'!$BT$7:$BT$371) -> 6249 | E5: =SUMIF('Traffic Data'!$F$7:$F$371,$A5,'Traffic Data'!$BX$7:$BX$371) -> 6096 | F5: =SUMIF('Traffic Data'!$F$7:$F$371,$A5,'Traffic Data'!$CB$7:$CB$371) -> 5974 | G5: =SUMIF('Traffic Data'!$F$7:$F$371,$A5,'Traffic Data'!$CF$7:$CF$371) -> 5334 | H5: =SUMIF('Traffic Data'!$F$7:$F$371,$A5,'Traffic Data'!$CJ$7:$CJ$371) -> 5017 | I5: =(H5-G5)/G5 -> -0.059430071
A6: =C6 -> 40513 | B6: 2011 | C6: ='Traffic Data'!BS9 -> 40513 | D6: =SUMIF('Traffic Data'!$F$7:$F$371,$A6,'Traffic Data'!$BT$7:$BT$371) -> 5517 | E6: =SUMIF('Traffic Data'!$F$7:$F$371,$A6,'Traffic Data'!$BX$7:$BX$371) -> 5387 | F6: =SUMIF('Traffic Data'!$F$7:$F$371,$A6,'Traffic Data'!$CB$7:$CB$371) -> 5404 | G6: =SUMIF('Traffic Data'!$F$7:$F$371,$A6,'Traffic Data'!$CF$7:$CF$371) -> 4825 | H6: =SUMIF('Traffic Data'!$F$7:$F$371,$A6,'Traffic Data'!$CJ$7:$CJ$371) -> 4511 | I6: =(H6-G6)/G6 -> -0.06507772
A7: =C7 -> 40544 | B7: 2011 | C7: ='Traffic Data'!BS10 -> 40544 | D7: =SUMIF('Traffic Data'!$F$7:$F$371,$A7,'Traffic Data'!$BT$7:$BT$371) -> 7273 | E7: =SUMIF('Traffic Data'!$F$7:$F$371,$A7,'Traffic Data'!$BX$7:$BX$371) -> 7520 | F7: =SUMIF('Traffic Data'!$F$7:$F$371,$A7,'Traffic Data'!$CB$7:$CB$371) -> 6970 | G7: =SUMIF('Traffic Data'!$F$7:$F$371,$A7,'Traffic Data'!$CF$7:$CF$371) -> 6305 | H7: =SUMIF('Traffic Data'!$F$7:$F$371,$A7,'Traffic Data'!$CJ$7:$CJ$371) -> 5318 | I7: =(H7-G7)/G7 -> -0.15654243
A8: =C8 -> 40575 | B8: 2011 | C8: ='Traffic Data'!BS11 -> 40575 | D8: =SUMIF('Traffic Data'!$F$7:$F$371,$A8,'Traffic Data'!$BT$7:$BT$371) -> 7373 | E8: =SUMIF('Traffic Data'!$F$7:$F$371,$A8,'Traffic Data'!$BX$7:$BX$371) -> 7496 | F8: =SUMIF('Traffic Data'!$F$7:$F$371,$A8,'Traffic Data'!$CB$7:$CB$371) -> 7294 | G8: =SUMIF('Traffic Data'!$F$7:$F$371,$A8,'Traffic Data'!$CF$7:$CF$371) -> 6757 | H8: =SUMIF('Traffic Data'!$F$7:$F$371,$A8,'Traffic Data'!$CJ$7:$CJ$371) -> 4442 | I8: =(H8-G8)/G8 -> -0.34260767
A9: =C9 -> 40603 | B9: 2011 | C9: ='Traffic Data'!BS12 -> 40603 | D9: =SUMIF('Traffic Data'!$F$7:$F$371,$A9,'Traffic Data'!$BT$7:$BT$371) -> 10455 | E9: =SUMIF('Traffic Data'!$F$7:$F$371,$A9,'Traffic Data'!$BX$7:$BX$371) -> 10246 | F9: =SUMIF('Traffic Data'!$F$7:$F$371,$A9,'Traffic Data'!$CB$7:$CB$371) -> 10020 | G9: =SUMIF('Traffic Data'!$F$7:$F$371,$A9,'Traffic Data'!$CF$7:$CF$371) -> 8736 | H9: =SUMIF('Traffic Data'!$F$7:$F$371,$A9,'Traffic Data'!$CJ$7:$CJ$371) -> 5402 | I9: =(H9-G9)/G9 -> -0.38163919
A10: =C10 -> 40634 | B10: 2011 | C10: ='Traffic Data'!BS13 -> 40634 | D10: =SUMIF('Traffic Data'!$F$7:$F$371,$A10,'Traffic Data'!$BT$7:$BT$371) -> 9474 | E10: =SUMIF('Traffic Data'!$F$7:$F$371,$A10,'Traffic Data'!$BX$7:$BX$371) -> 9291 | F10: =SUMIF('Traffic Data'!$F$7:$F$371,$A10,'Traffic Data'!$CB$7:$CB$371) -> 9141 | G10: =SUMIF('Traffic Data'!$F$7:$F$371,$A10,'Traffic Data'!$CF$7:$CF$371) -> 8156 | H10: =SUMIF('Traffic Data'!$F$7:$F$371,$A10,'Traffic Data'!$CJ$7:$CJ$371) -> 5172 | I10: =(H10-G10)/G10 -> -0.36586562
A11: =C11 -> 40664 | B11: 2011 | C11: ='Traffic Data'!BS14 -> 40664 | D11: =SUMIF('Traffic Data'!$F$7:$F$371,$A11,'Traffic Data'!$BT$7:$BT$371) -> 8431 | E11: =SUMIF('Traffic Data'!$F$7:$F$371,$A11,'Traffic Data'!$BX$7:$BX$371) -> 8226 | F11: =SUMIF('Traffic Data'!$F$7:$F$371,$A11,'Traffic Data'!$CB$7:$CB$371) -> 7890 | G11: =SUMIF('Traffic Data'!$F$7:$F$371,$A11,'Traffic Data'!$CF$7:$CF$371) -> 7410 | H11: =SUMIF('Traffic Data'!$F$7:$F$371,$A11,'Traffic Data'!$CJ$7:$CJ$371) -> 4310 | I11: =(H11-G11)/G11 -> -0.41835358
A12: =C12 -> 40695 | B12: 2011 | C12: ='Traffic Data'!BS15 -> 40695 | D12: =SUMIF('Traffic Data'!$F$7:$F$371,$A12,'Traffic Data'!$BT$7:$BT$371) -> 3463 | E12: =SUMIF('Traffic Data'!$F$7:$F$371,$A12,'Traffic Data'!$BX$7:$BX$371) -> 3409 | F12: =SUMIF('Traffic Data'!$F$7:$F$371,$A12,'Traffic Data'!$CB$7:$CB$371) -> 3296 | G12: =SUMIF('Traffic Data'!$F$7:$F$371,$A12,'Traffic Data'!$CF$7:$CF$371) -> 3066 | H12: =SUMIF('Traffic Data'!$F$7:$F$371,$A12,'Traffic Data'!$CJ$7:$CJ$371) -> 2053 | I12: =(H12-G12)/G12 -> -0.33039791
A13: =C13 -> 40725 | B13: 2011 | C13: ='Traffic Data'!BS16 -> 40725 | D13: =SUMIF('Traffic Data'!$F$7:$F$371,$A13,'Traffic Data'!$BT$7:$BT$371) -> 7869 | E13: =SUMIF('Traffic Data'!$F$7:$F$371,$A13,'Traffic Data'!$BX$7:$BX$371) -> 7745 | F13: =SUMIF('Traffic Data'!$F$7:$F$371,$A13,'Traffic Data'!$CB$7:$CB$371) -> 7600 | G13: =SUMIF('Traffic Data'!$F$7:$F$371,$A13,'Traffic Data'!$CF$7:$CF$371) -> 7154 | H13: =SUMIF('Traffic Data'!$F$7:$F$371,$A13,'Traffic Data'!$CJ$7:$CJ$371) -> 4160 | I13: =(H13-G13)/G13 -> -0.41850713
A14: =C14 -> 40756 | B14: 2011 | C14: ='Traffic Data'!BS17 -> 40756 | D14: =SUMIF('Traffic Data'!$F$7:$F$371,$A14,'Traffic Data'!$BT$7:$BT$371) -> 7485 | E14: =SUMIF('Traffic Data'!$F$7:$F$371,$A14,'Traffic Data'!$BX$7:$BX$371) -> 7330 | F14: =SUMIF('Traffic Data'!$F$7:$F$371,$A14,'Traffic Data'!$CB$7:$CB$371) -> 7175 | G14: =SUMIF('Traffic Data'!$F$7:$F$371,$A14,'Traffic Data'!$CF$7:$CF$371) -> 6775 | H14: =SUMIF('Traffic Data'!$F$7:$F$371,$A14,'Traffic Data'!$CJ$7:$CJ$371) -> 3749 | I14: =(H14-G14)/G14 -> -0.44664207
A15: =C15 -> 40787 | B15: 2011 | C15: ='Traffic Data'!BS18 -> 40787 | D15: =SUMIF('Traffic Data'!$F$7:$F$371,$A15,'Traffic Data'!$BT$7:$BT$371) -> 7815 | E15: =SUMIF('Traffic Data'!$F$7:$F$371,$A15,'Traffic Data'!$BX$7:$BX$371) -> 7598 | F15: =SUMIF('Traffic Data'!$F$7:$F$371,$A15,'Traffic Data'!$CB$7:$CB$371) -> 7454 | G15: =SUMIF('Traffic Data'!$F$7:$F$371,$A15,'Traffic Data'!$CF$7:$CF$371) -> 6952 | H15: =SUMIF('Traffic Data'!$F$7:$F$371,$A15,'Traffic Data'!$CJ$7:$CJ$371) -> 4068 | I15: =(H15-G15)/G15 -> -0.41484465
... A27: =C27 -> 41153 | B27: 2023 | C27: ='Traffic Data'!BS30 -> 41153 | D27: =SUMIF('Traffic Data'!$F$7:$F$371,$A27,'Traffic Data'!$BT$7:$BT$371) -> 8384 | E27: =SUMIF('Traffic Data'!$F$7:$F$371,$A27,'Traffic Data'!$BX$7:$BX$371) -> 5406 | F27: =SUMIF('Traffic Data'!$F$7:$F$371,$A27,'Traffic Data'!$CB$7:$CB$371) -> 7284 | G27: =SUMIF('Traffic Data'!$F$7:$F$371,$A27,'Traffic Data'!$CF$7:$CF$371) -> 6546 | H27: =SUMIF('Traffic Data'!$F$7:$F$371,$A27,'Traffic Data'!$CJ$7:$CJ$371) -> 6026 | I27: =(H27-G27)/G27 -> -0.079437825
A29: YTD | B29: 2011 | C29: Total | D29: =SUM(D4:D15) -> 86470 | E29: =SUM(E4:E15) -> 85274 | F29: =SUM(F4:F15) -> 83047 | G29: =SUM(G4:G15) -> 75912 | H29: =SUM(H4:H15) -> 52365

Sheet Conversion Data
A1: Report Suite | B1: =Config!B1 -> canadapostca-global
A3: Date From | B3: =Config!B3 -> 40269
A4: Date To | B4: =Config!B4 -> 40999 | K4: Conversion: Site Section 1
K5: ="Conversion Events: " & ORB_V1_sh2_111110035412386 -> Conversion Events: cpc.ca: shop | AF5: Conversion Events: Organic Search | AN5: ORGANIC SEARCH | AQ5: Conversion Events: Paid Search | AY5: PAID SEARCH | BB5: Conversion Events: Mobile | BJ5: MOBILE
A6: Search Terms | D6: weekID | E6: D-O-W | F6: DateID | G6: dayID | H6: yearID | I6: dateID | K6: Metrics | L6: Site: Revenue | M6: Site: Orders | N6: Site: Units | O6: Shop: Checkouts | P6: Shop: Carts | Q6: Shop: Cart Additions | R6: Shop: Cart Removals | AF6: Metrics | AG6: Site: Revenue | AH6: Site: Orders | AI6: Site: Units | AJ6: Shop: Checkouts | AK6: Shop: Carts | AL6: Shop: Cart Additions | AM6: Shop: Cart Removals | AN6: % Revenue | AO6: % Orders | AQ6: Metrics | AR6: Site: Revenue | AS6: Site: Orders | AT6: Site: Units | AU6: Shop: Checkouts | AV6: Shop: Carts | AW6: Shop: Cart Additions | AX6: Shop: Cart Removals | AY6: % Revenue | AZ6: % Orders | BB6: Metrics | BC6: Site: Revenue | BD6: Site: Orders | BE6: Site: Units | BF6: Shop: Checkouts | BG6: Shop: Carts | BH6: Shop: Cart Additions | BI6: Shop: Cart Removals | BJ6: % Revenue | BK6: % Orders
A7: =IF(Config!A7 <> "",Config!A7,"") -> ss1 | B7: =IF(Config!B7<>"",Config!B7,"") -> cpc.ca: shop | D7: =IF(K7<>"",1+INT((K7-(DATE(YEAR(K7),1,2)-WEEKDAY(DATE(YEAR(K7),1,1))))/7),"") -> 40 | E7: =IF(K7<>"",TEXT(K7,"ddd"),"") -> Fri | F7: =K7 -> 40452 | G7: =IF(K7<>"",DAY(K7),"") -> 1 | H7: =IF(K7<>"",YEAR(K7),"") -> 2010 | K7: 40452 | L7: 802006.2 | M7: 4534 | N7: 217175 | O7: 7104 | P7: 9992 | Q7: 29428 | R7: 3146 | AF7: 40452 | AG7: 0 | AH7: 0 | AI7: 0 | AJ7: 0 | AK7: 0 | AL7: 0 | AM7: 0 | AQ7: 40452 | AR7: 0 | AS7: 0 | AT7: 0 | AU7: 0 | AV7: 0 | AW7: 0 | AX7: 0 | BB7: 40452 | BC7: 0 | BD7: 0 | BE7: 0 | BF7: 0 | BG7: 0 | BH7: 0 | BI7: 0
A8: =IF(Config!A8 <> "",Config!A8,"") -> ss2 | B8: =IF(Config!B8<>"",Config!B8,"") -> cpc.ca: shop > business | D8: =IF(K8<>"",1+INT((K8-(DATE(YEAR(K8),1,2)-WEEKDAY(DATE(YEAR(K8),1,1))))/7),"") -> 45 | E8: =IF(K8<>"",TEXT(K8,"ddd"),"") -> Mon | F8: =K8 -> 40483 | G8: =IF(K8<>"",DAY(K8),"") -> 1 | H8: =IF(K8<>"",YEAR(K8),"") -> 2010 | K8: 40483 | L8: 1080700.5 | M8: 5467 | N8: 261038 | O8: 8943 | P8: 11810 | Q8: 31025 | R8: 3364 | AF8: 40483 | AG8: 0 | AH8: 0 | AI8: 0 | AJ8: 0 | AK8: 0 | AL8: 0 | AM8: 0 | AQ8: 40483 | AR8: 0 | AS8: 0 | AT8: 0 | AU8: 0 | AV8: 0 | AW8: 0 | AX8: 0 | BB8: 40483 | BC8: 0 | BD8: 0 | BE8: 0 | BF8: 0 | BG8: 0 | BH8: 0 | BI8: 0
A9: =IF(Config!A9 <> "",Config!A9,"") -> ss2 | B9: =IF(Config!B9<>"",Config!B9,"") -> cpc.ca: shop > commercial | D9: =IF(K9<>"",1+INT((K9-(DATE(YEAR(K9),1,2)-WEEKDAY(DATE(YEAR(K9),1,1))))/7),"") -> 49 | E9: =IF(K9<>"",TEXT(K9,"ddd"),"") -> Wed | F9: =K9 -> 40513 | G9: =IF(K9<>"",DAY(K9),"") -> 1 | H9: =IF(K9<>"",YEAR(K9),"") -> 2010 | K9: 40513 | L9: 922841.98 | M9: 4937 | N9: 227793 | O9: 8017 | P9: 11570 | Q9: 35447 | R9: 3279 | AF9: 40513 | AG9: 0 | AH9: 0 | AI9: 0 | AJ9: 0 | AK9: 0 | AL9: 0 | AM9: 0 | AQ9: 40513 | AR9: 0 | AS9: 0 | AT9: 0 | AU9: 0 | AV9: 0 | AW9: 0 | AX9: 0 | BB9: 40513 | BC9: 0 | BD9: 0 | BE9: 0 | BF9: 0 | BG9: 0 | BH9: 0 | BI9: 0
A10: =IF(Config!A10 <> "",Config!A10,"") -> ss2 | B10: =IF(Config!B10<>"",Config!B10,"") -> cpc.ca: shop > personal | D10: =IF(K10<>"",1+INT((K10-(DATE(YEAR(K10),1,2)-WEEKDAY(DATE(YEAR(K10),1,1))))/7),"") -> 1 | E10: =IF(K10<>"",TEXT(K10,"ddd"),"") -> Sat | F10: =K10 -> 40544 | G10: =IF(K10<>"",DAY(K10),"") -> 1 | H10: =IF(K10<>"",YEAR(K10),"") -> 2011 | K10: 40544 | L10: 838971.47 | M10: 5803 | N10: 246422 | O10: 11182 | P10: 19663 | Q10: 60906 | R10: 5139 | AF10: 40544 | AG10: 0 | AH10: 0 | AI10: 0 | AJ10: 0 | AK10: 0 | AL10: 0 | AM10: 0 | AQ10: 40544 | AR10: 0 | AS10: 0 | AT10: 0 | AU10: 0 | AV10: 0 | AW10: 0 | AX10: 0 | BB10: 40544 | BC10: 0 | BD10: 0 | BE10: 0 | BF10: 0 | BG10: 0 | BH10: 0 | BI10: 0
A11: =IF(Config!A11 <> "",Config!A11,"") -> ss2 | B11: =IF(Config!B11<>"",Config!B11,"") -> cpc.ca: shop > collecting | D11: =IF(K11<>"",1+INT((K11-(DATE(YEAR(K11),1,2)-WEEKDAY(DATE(YEAR(K11),1,1))))/7),"") -> 6 | E11: =IF(K11<>"",TEXT(K11,"ddd"),"") -> Tue | F11: =K11 -> 40575 | G11: =IF(K11<>"",DAY(K11),"") -> 1 | H11: =IF(K11<>"",YEAR(K11),"") -> 2011 | K11: 40575 | L11: 743280.91 | M11: 4864 | N11: 205251 | O11: 9936 | P11: 13901 | Q11: 35867 | R11: 3423 | AF11: 40575 | AG11: 0 | AH11: 0 | AI11: 0 | AJ11: 0 | AK11: 0 | AL11: 0 | AM11: 0 | AQ11: 40575 | AR11: 0 | AS11: 0 | AT11: 0 | AU11: 0 | AV11: 0 | AW11: 0 | AX11: 0 | BB11: 40575 | BC11: 0 | BD11: 0 | BE11: 0 | BF11: 0 | BG11: 0 | BH11: 0 | BI11: 0
A12: =IF(Config!A12 <> "",Config!A12,"") -> site | B12: =IF(Config!B12<>"",Config!B12,"") -> cpc.ca | D12: =IF(K12<>"",1+INT((K12-(DATE(YEAR(K12),1,2)-WEEKDAY(DATE(YEAR(K12),1,1))))/7),"") -> 10 | E12: =IF(K12<>"",TEXT(K12,"ddd"),"") -> Tue | F12: =K12 -> 40603 | G12: =IF(K12<>"",DAY(K12),"") -> 1 | H12: =IF(K12<>"",YEAR(K12),"") -> 2011 | K12: 40603 | L12: 1039483.8 | M12: 5987 | N12: 267414 | O12: 13421 | P12: 13968 | Q12: 33541 | R12: 3270 | AF12: 40603 | AG12: 0 | AH12: 0 | AI12: 0 | AJ12: 0 | AK12: 0 | AL12: 0 | AM12: 0 | AQ12: 40603 | AR12: 0 | AS12: 0 | AT12: 0 | AU12: 0 | AV12: 0 | AW12: 0 | AX12: 0 | BB12: 40603 | BC12: 0 | BD12: 0 | BE12: 0 | BF12: 0 | BG12: 0 | BH12: 0 | BI12: 0
A13: =IF(Config!A13 <> "",Config!A13,"") -> basic page | B13: =IF(Config!B13<>"",Config!B13,"") -> cpc.ca: shop > checkout > address information | D13: =IF(K13<>"",1+INT((K13-(DATE(YEAR(K13),1,2)-WEEKDAY(DATE(YEAR(K13),1,1))))/7),"") -> 14 | E13: =IF(K13<>"",TEXT(K13,"ddd"),"") -> Fri | F13: =K13 -> 40634 | G13: =IF(K13<>"",DAY(K13),"") -> 1 | H13: =IF(K13<>"",YEAR(K13),"") -> 2011 | K13: 40634 | L13: 910968.43 | M13: 5682 | N13: 228846 | O13: 12397 | P13: 12811 | Q13: 39308 | R13: 4233 | AF13: 40634 | AG13: 0 | AH13: 0 | AI13: 0 | AJ13: 0 | AK13: 0 | AL13: 0 | AM13: 0 | AQ13: 40634 | AR13: 0 | AS13: 0 | AT13: 0 | AU13: 0 | AV13: 0 | AW13: 0 | AX13: 0 | BB13: 40634 | BC13: 0 | BD13: 0 | BE13: 0 | BF13: 0 | BG13: 0 | BH13: 0 | BI13: 0
A14: =IF(Config!A14 <> "",Config!A14,"") -> basic page | B14: =IF(Config!B14<>"",Config!B14,"") -> cpc.ca: shop > checkout > shipping options | D14: =IF(K14<>"",1+INT((K14-(DATE(YEAR(K14),1,2)-WEEKDAY(DATE(YEAR(K14),1,1))))/7),"") -> 19 | E14: =IF(K14<>"",TEXT(K14,"ddd"),"") -> Sun | F14: =K14 -> 40664 | G14: =IF(K14<>"",DAY(K14),"") -> 1 | H14: =IF(K14<>"",YEAR(K14),"") -> 2011 | K14: 40664 | L14: 913710.23 | M14: 4708 | N14: 219446 | O14: 10955 | P14: 11881 | Q14: 29249 | R14: 2959 | AF14: 40664 | AG14: 0 | AH14: 0 | AI14: 0 | AJ14: 0 | AK14: 0 | AL14: 0 | AM14: 0 | AQ14: 40664 | AR14: 0 | AS14: 0 | AT14: 0 | AU14: 0 | AV14: 0 | AW14: 0 | AX14: 0 | BB14: 40664 | BC14: 0 | BD14: 0 | BE14: 0 | BF14: 0 | BG14: 0 | BH14: 0 | BI14: 0
A15: =IF(Config!A15 <> "",Config!A15,"") -> basic page | B15: =IF(Config!B15<>"",Config!B15,"") -> cpc.ca: shop > checkout > payment options | D15: =IF(K15<>"",1+INT((K15-(DATE(YEAR(K15),1,2)-WEEKDAY(DATE(YEAR(K15),1,1))))/7),"") -> 23 | E15: =IF(K15<>"",TEXT(K15,"ddd"),"") -> Wed | F15: =K15 -> 40695 | G15: =IF(K15<>"",DAY(K15),"") -> 1 | H15: =IF(K15<>"",YEAR(K15),"") -> 2011 | K15: 40695 | L15: 420709.3 | M15: 2241 | N15: 107232 | O15: 4518 | P15: 4081 | Q15: 10485 | R15: 1227 | AF15: 40695 | AG15: 0 | AH15: 0 | AI15: 0 | AJ15: 0 | AK15: 0 | AL15: 0 | AM15: 0 | AQ15: 40695 | AR15: 0 | AS15: 0 | AT15: 0 | AU15: 0 | AV15: 0 | AW15: 0 | AX15: 0 | BB15: 40695 | BC15: 0 | BD15: 0 | BE15: 0 | BF15: 0 | BG15: 0 | BH15: 0 | BI15: 0
A16: =IF(Config!A16 <> "",Config!A16,"") -> basic page | B16: =IF(Config!B16<>"",Config!B16,"") -> cpc.ca: shop > checkout > place order | D16: =IF(K16<>"",1+INT((K16-(DATE(YEAR(K16),1,2)-WEEKDAY(DATE(YEAR(K16),1,1))))/7),"") -> 27 | E16: =IF(K16<>"",TEXT(K16,"ddd"),"") -> Fri | F16: =K16 -> 40725 | G16: =IF(K16<>"",DAY(K16),"") -> 1 | H16: =IF(K16<>"",YEAR(K16),"") -> 2011 | K16: 40725 | L16: 758817.4 | M16: 4524 | N16: 197850 | O16: 10154 | P16: 12129 | Q16: 28952 | R16: 2800 | AF16: 40725 | AG16: 0 | AH16: 0 | AI16: 0 | AJ16: 0 | AK16: 0 | AL16: 0 | AM16: 0 | AQ16: 40725 | AR16: 0 | AS16: 0 | AT16: 0 | AU16: 0 | AV16: 0 | AW16: 0 | AX16: 0 | BB16: 40725 | BC16: 0 | BD16: 0 | BE16: 0 | BF16: 0 | BG16: 0 | BH16: 0 | BI16: 0
A17: =IF(Config!A17 <> "",Config!A17,"") -> basic page | B17: =IF(Config!B17<>"",Config!B17,"") -> cpc.ca: shop > checkout > order confirmation | D17: =IF(K17<>"",1+INT((K17-(DATE(YEAR(K17),1,2)-WEEKDAY(DATE(YEAR(K17),1,1))))/7),"") -> 32 | E17: =IF(K17<>"",TEXT(K17,"ddd"),"") -> Mon | F17: =K17 -> 40756 | G17: =IF(K17<>"",DAY(K17),"") -> 1 | H17: =IF(K17<>"",YEAR(K17),"") -> 2011 | K17: 40756 | L17: 731942.55 | M17: 4059 | N17: 199333 | O17: 9790 | P17: 12706 | Q17: 24237 | R17: 2442 | AF17: 40756 | AG17: 0 | AH17: 0 | AI17: 0 | AJ17: 0 | AK17: 0 | AL17: 0 | AM17: 0 | AQ17: 40756 | AR17: 0 | AS17: 0 | AT17: 0 | AU17: 0 | AV17: 0 | AW17: 0 | AX17: 0 | BB17: 40756 | BC17: 0 | BD17: 0 | BE17: 0 | BF17: 0 | BG17: 0 | BH17: 0 | BI17: 0
A18: =IF(Config!A18 <> "",Config!A18,"") | B18: =IF(Config!B18<>"",Config!B18,"") | D18: =IF(K18<>"",1+INT((K18-(DATE(YEAR(K18),1,2)-WEEKDAY(DATE(YEAR(K18),1,1))))/7),"") -> 36 | E18: =IF(K18<>"",TEXT(K18,"ddd"),"") -> Thu | F18: =K18 -> 40787 | G18: =IF(K18<>"",DAY(K18),"") -> 1 | H18: =IF(K18<>"",YEAR(K18),"") -> 2011 | K18: 40787 | L18: 667614.84 | M18: 3345 | N18: 146724 | O18: 7840 | P18: 13480 | Q18: 25689 | R18: 2484 | AF18: 40787 | AG18: 0 | AH18: 0 | AI18: 0 | AJ18: 0 | AK18: 0 | AL18: 0 | AM18: 0 | AQ18: 40787 | AR18: 0 | AS18: 0 | AT18: 0 | AU18: 0 | AV18: 0 | AW18: 0 | AX18: 0 | BB18: 40787 | BC18: 0 | BD18: 0 | BE18: 0 | BF18: 0 | BG18: 0 | BH18: 0 | BI18: 0
... A27: =IF(Config!A27 <> "",Config!A27,"") | B27: =IF(Config!B27<>"",Config!B27,"") | D27: =IF(K27<>"",1+INT((K27-(DATE(YEAR(K27),1,2)-WEEKDAY(DATE(YEAR(K27),1,1))))/7),"") -> 22 | E27: =IF(K27<>"",TEXT(K27,"ddd"),"") -> Fri | F27: =K27 -> 41061 | G27: =IF(K27<>"",DAY(K27),"") -> 1 | H27: =IF(K27<>"",YEAR(K27),"") -> 2012 | K27: 41061 | L27: 1048588.9 | M27: 6314 | N27: 172140 | O27: 12138 | P27: 12384 | Q27: 37263 | R27: 5152 | AF27: 41061 | AG27: 244376.93 | AH27: 1738 | AI27: 33310 | AJ27: 3832 | AK27: 4477 | AL27: 12466 | AM27: 1631 | AQ27: 41061 | AR27: 14741.93 | AS27: 133 | AT27: 1550 | AU27: 313 | AV27: 462 | AW27: 1075 | AX27: 140 | BB27: 41061 | BC27: 32606.94 | BD27: 123 | BE27: 820 | BF27: 383 | BG27: 269 | BH27: 829 | BI27: 130
A28: =IF(Config!A28 <> "",Config!A28,"") | B28: =IF(Config!B28<>"",Config!B28,"") | D28: =IF(K28<>"",1+INT((K28-(DATE(YEAR(K28),1,2)-WEEKDAY(DATE(YEAR(K28),1,1))))/7),"") -> 27 | E28: =IF(K28<>"",TEXT(K28,"ddd"),"") -> Sun | F28: =K28 -> 41091 | G28: =IF(K28<>"",DAY(K28),"") -> 1 | H28: =IF(K28<>"",YEAR(K28),"") -> 2012 | K28: 41091 | L28: 942676.24 | M28: 5813 | N28: 152106 | O28: 11276 | P28: 11949 | Q28: 32082 | R28: 4780 | AF28: 41091 | AG28: 201899.96 | AH28: 1502 | AI28: 23206 | AJ28: 3339 | AK28: 4139 | AL28: 10427 | AM28: 1452 | AN28: =AG28/L28 -> 0.21417741 | AO28: =AH28/M28 -> 0.25838638 | AQ28: 41091 | AR28: 16887.26 | AS28: 94 | AT28: 1959 | AU28: 229 | AV28: 388 | AW28: 843 | AX28: 89 | AY28: =AR28/$L28 -> 0.017914167 | AZ28: =AS28/$M28 -> 0.016170652 | BB28: 41091 | BC28: 16841.01 | BD28: 128 | BE28: 1250 | BF28: 347 | BG28: 285 | BH28: 787 | BI28: 161 | BJ28: =BC28/$L28 -> 0.017865105 | BK28: =BD28/$M28 -> 0.022019611
A29: =IF(Config!A29 <> "",Config!A29,"") | B29: =IF(Config!B29<>"",Config!B29,"") | D29: =IF(K29<>"",1+INT((K29-(DATE(YEAR(K29),1,2)-WEEKDAY(DATE(YEAR(K29),1,1))))/7),"") -> 31 | E29: =IF(K29<>"",TEXT(K29,"ddd"),"") -> Wed | F29: =K29 -> 41122 | G29: =IF(K29<>"",DAY(K29),"") -> 1 | H29: =IF(K29<>"",YEAR(K29),"") -> 2012 | K29: 41122 | L29: 1013093.5 | M29: 5751 | N29: 180818 | O29: 11339 | P29: 9207 | Q29: 23820 | R29: 3409 | AF29: 41122 | AG29: 235371.32 | AH29: 1498 | AI29: 30967 | AJ29: 3381 | AK29: 3155 | AL29: 7692 | AM29: 1129 | AN29: =AG29/L29 -> 0.23232932 | AO29: =AH29/M29 -> 0.26047644 | AQ29: 41122 | AR29: 8781.37 | AS29: 71 | AT29: 753 | AU29: 156 | AV29: 207 | AW29: 464 | AX29: 57 | AY29: =AR29/$L29 -> 0.0086678773 | AZ29: =AS29/$M29 -> 0.012345679 | BB29: 41122 | BC29: 15899.1 | BD29: 133 | BE29: 1080 | BF29: 386 | BG29: 223 | BH29: 628 | BI29: 85 | BJ29: =BC29/$L29 -> 0.015693616 | BK29: =BD29/$M29 -> 0.023126413
A30: =IF(Config!A30 <> "",Config!A30,"") | B30: =IF(Config!B30<>"",Config!B30,"") | D30: =IF(K30<>"",1+INT((K30-(DATE(YEAR(K30),1,2)-WEEKDAY(DATE(YEAR(K30),1,1))))/7),"") -> 35 | E30: =IF(K30<>"",TEXT(K30,"ddd"),"") -> Sat | F30: =K30 -> 41153 | G30: =IF(K30<>"",DAY(K30),"") -> 1 | H30: =IF(K30<>"",YEAR(K30),"") -> 2012 | K30: 41153 | L30: 1015548.9 | M30: 6204 | N30: 169304 | O30: 11650 | P30: 9579 | Q30: 27450 | R30: 3397 | AF30: 41153 | AG30: 232086.23 | AH30: 1640 | AI30: 27496 | AJ30: 3623 | AK30: 3431 | AL30: 8667 | AM30: 1121 | AN30: =AG30/L30 -> 0.2285328 | AO30: =AH30/M30 -> 0.26434558 | AQ30: 41153 | AR30: 14870.89 | AS30: 81 | AT30: 998 | AU30: 212 | AV30: 220 | AW30: 525 | AX30: 39 | AY30: =AR30/$L30 -> 0.014643205 | AZ30: =AS30/$M30 -> 0.013056093 | BB30: 41153 | BC30: 24558 | BD30: 151 | BE30: 1073 | BF30: 407 | BG30: 285 | BH30: 805 | BI30: 100 | BJ30: =BC30/$L30 -> 0.024181997 | BK30: =BD30/$M30 -> 0.024339136
AF31: 41000 | AG31: 4493.15 | AH31: 56 | AI31: 383 | AJ31: 124 | AK31: 146 | AL31: 475 | AM31: 76 | AQ31: 41000 | AR31: 0 | AS31: 0 | AT31: 0 | AU31: 2 | AV31: 11 | AW31: 14 | AX31: 0 | BB31: 41000 | BC31: 575.07 | BD31: 9 | BE31: 101 | BF31: 33 | BG31: 20 | BH31: 70 | BI31: 12
A32: =IF(Config!A32 <> "",Config!A32,"") | B32: =IF(Config!B32<>"",Config!B32,"") | D32: =IF(K32<>"",1+INT((K32-(DATE(YEAR(K32),1,2)-WEEKDAY(DATE(YEAR(K32),1,1))))/7),"") | E32: =IF(K32<>"",TEXT(K32,"ddd"),"") | F32: =IF(K32<>"",MONTH(K32),"") | G32: =IF(K32<>"",DAY(K32),"") | H32: =IF(K32<>"",YEAR(K32),"")
A33: =IF(Config!A33 <> "",Config!A33,"") | B33: =IF(Config!B33<>"",Config!B33,"") | D33: =IF(K33<>"",1+INT((K33-(DATE(YEAR(K33),1,2)-WEEKDAY(DATE(YEAR(K33),1,1))))/7),"") | E33: =IF(K33<>"",TEXT(K33,"ddd"),"") | F33: =IF(K33<>"",MONTH(K33),"") | G33: =IF(K33<>"",DAY(K33),"") | H33: =IF(K33<>"",YEAR(K33),"")
A34: =IF(Config!A34 <> "",Config!A34,"") | B34: =IF(Config!B34<>"",Config!B34,"") | D34: =IF(K34<>"",1+INT((K34-(DATE(YEAR(K34),1,2)-WEEKDAY(DATE(YEAR(K34),1,1))))/7),"") | E34: =IF(K34<>"",TEXT(K34,"ddd"),"") | F34: =IF(K34<>"",MONTH(K34),"") | G34: =IF(K34<>"",DAY(K34),"") | H34: =IF(K34<>"",YEAR(K34),"")
A35: =IF(Config!A35 <> "",Config!A35,"") | B35: =IF(Config!B35<>"",Config!B35,"") | D35: =IF(K35<>"",1+INT((K35-(DATE(YEAR(K35),1,2)-WEEKDAY(DATE(YEAR(K35),1,1))))/7),"") | E35: =IF(K35<>"",TEXT(K35,"ddd"),"") | F35: =IF(K35<>"",MONTH(K35),"") | G35: =IF(K35<>"",DAY(K35),"") | H35: =IF(K35<>"",YEAR(K35),"")
A36: =IF(Config!A36 <> "",Config!A36,"") | B36: =IF(Config!B36<>"",Config!B36,"") | D36: =IF(K36<>"",1+INT((K36-(DATE(YEAR(K36),1,2)-WEEKDAY(DATE(YEAR(K36),1,1))))/7),"") | E36: =IF(K36<>"",TEXT(K36,"ddd"),"") | F36: =IF(K36<>"",MONTH(K36),"") | G36: =IF(K36<>"",DAY(K36),"") | H36: =IF(K36<>"",YEAR(K36),"")
A37: =IF(Config!A37 <> "",Config!A37,"") | B37: =IF(Config!B37<>"",Config!B37,"") | D37: =IF(K37<>"",1+INT((K37-(DATE(YEAR(K37),1,2)-WEEKDAY(DATE(YEAR(K37),1,1))))/7),"") | E37: =IF(K37<>"",TEXT(K37,"ddd"),"") | F37: =IF(K37<>"",MONTH(K37),"") | G37: =IF(K37<>"",DAY(K37),"") | H37: =IF(K37<>"",YEAR(K37),"")
A38: =IF(Config!A38 <> "",Config!A38,"") | B38: =IF(Config!B38<>"",Config!B38,"") | D38: =IF(K38<>"",1+INT((K38-(DATE(YEAR(K38),1,2)-WEEKDAY(DATE(YEAR(K38),1,1))))/7),"") | E38: =IF(K38<>"",TEXT(K38,"ddd"),"") | F38: =IF(K38<>"",MONTH(K38),"") | G38: =IF(K38<>"",DAY(K38),"") | H38: =IF(K38<>"",YEAR(K38),"")
A39: =IF(Config!A39 <> "",Config!A39,"") | B39: =IF(Config!B39<>"",Config!B39,"") | D39: =IF(K39<>"",1+INT((K39-(DATE(YEAR(K39),1,2)-WEEKDAY(DATE(YEAR(K39),1,1))))/7),"") | E39: =IF(K39<>"",TEXT(K39,"ddd"),"") | F39: =IF(K39<>"",MONTH(K39),"") | G39: =IF(K39<>"",DAY(K39),"") | H39: =IF(K39<>"",YEAR(K39),"")
A40: =IF(Config!A40 <> "",Config!A40,"") | B40: =IF(Config!B40<>"",Config!B40,"") | D40: =IF(K40<>"",1+INT((K40-(DATE(YEAR(K40),1,2)-WEEKDAY(DATE(YEAR(K40),1,1))))/7),"") | E40: =IF(K40<>"",TEXT(K40,"ddd"),"") | F40: =IF(K40<>"",MONTH(K40),"") | G40: =IF(K40<>"",DAY(K40),"") | H40: =IF(K40<>"",YEAR(K40),"")
A41: =IF(Config!A41 <> "",Config!A41,"") | B41: =IF(Config!B41<>"",Config!B41,"") | D41: =IF(K41<>"",1+INT((K41-(DATE(YEAR(K41),1,2)-WEEKDAY(DATE(YEAR(K41),1,1))))/7),"") | E41: =IF(K41<>"",TEXT(K41,"ddd"),"") | F41: =IF(K41<>"",MONTH(K41),"") | G41: =IF(K41<>"",DAY(K41),"") | H41: =IF(K41<>"",YEAR(K41),"")
D42: =IF(K42<>"",1+INT((K42-(DATE(YEAR(K42),1,2)-WEEKDAY(DATE(YEAR(K42),1,1))))/7),"") | E42: =IF(K42<>"",TEXT(K42,"ddd"),"") | F42: =IF(K42<>"",MONTH(K42),"") | G42: =IF(K42<>"",DAY(K42),"") | H42: =IF(K42<>"",YEAR(K42),"")
D43: =IF(K43<>"",1+INT((K43-(DATE(YEAR(K43),1,2)-WEEKDAY(DATE(YEAR(K43),1,1))))/7),"") | E43: =IF(K43<>"",TEXT(K43,"ddd"),"") | F43: =IF(K43<>"",MONTH(K43),"") | G43: =IF(K43<>"",DAY(K43),"") | H43: =IF(K43<>"",YEAR(K43),"")
D44: =IF(K44<>"",1+INT((K44-(DATE(YEAR(K44),1,2)-WEEKDAY(DATE(YEAR(K44),1,1))))/7),"") | E44: =IF(K44<>"",TEXT(K44,"ddd"),"") | F44: =IF(K44<>"",MONTH(K44),"") | G44: =IF(K44<>"",DAY(K44),"") | H44: =IF(K44<>"",YEAR(K44),"")
D45: =IF(K45<>"",1+INT((K45-(DATE(YEAR(K45),1,2)-WEEKDAY(DATE(YEAR(K45),1,1))))/7),"") | E45: =IF(K45<>"",TEXT(K45,"ddd"),"") | F45: =IF(K45<>"",MONTH(K45),"") | G45: =IF(K45<>"",DAY(K45),"") | H45: =IF(K45<>"",YEAR(K45),"")
D46: =IF(K46<>"",1+INT((K46-(DATE(YEAR(K46),1,2)-WEEKDAY(DATE(YEAR(K46),1,1))))/7),"") | E46: =IF(K46<>"",TEXT(K46,"ddd"),"") | F46: =IF(K46<>"",MONTH(K46),"") | G46: =IF(K46<>"",DAY(K46),"") | H46: =IF(K46<>"",YEAR(K46),"")
D47: =IF(K47<>"",1+INT((K47-(DATE(YEAR(K47),1,2)-WEEKDAY(DATE(YEAR(K47),1,1))))/7),"") | E47: =IF(K47<>"",TEXT(K47,"ddd"),"") | F47: =IF(K47<>"",MONTH(K47),"") | G47: =IF(K47<>"",DAY(K47),"") | H47: =IF(K47<>"",YEAR(K47),"")
D48: =IF(K48<>"",1+INT((K48-(DATE(YEAR(K48),1,2)-WEEKDAY(DATE(YEAR(K48),1,1))))/7),"") | E48: =IF(K48<>"",TEXT(K48,"ddd"),"") | F48: =IF(K48<>"",MONTH(K48),"") | G48: =IF(K48<>"",DAY(K48),"") | H48: =IF(K48<>"",YEAR(K48),"")
D49: =IF(K49<>"",1+INT((K49-(DATE(YEAR(K49),1,2)-WEEKDAY(DATE(YEAR(K49),1,1))))/7),"") | E49: =IF(K49<>"",TEXT(K49,"ddd"),"") | F49: =IF(K49<>"",MONTH(K49),"") | G49: =IF(K49<>"",DAY(K49),"") | H49: =IF(K49<>"",YEAR(K49),"")
...

Sheet Traffic Data
A1: Report Suite | B1: =Config!B1 -> canadapostca-global
A3: Date From | B3: =Config!B3 -> 40269
A4: Date To | B4: =Config!B4 -> 40999 | K4: Traffic: Site Section 1 | U4: Traffic: Site Section 2 | AD4: Traffic: Site Section 2 | AR4: Traffic: Site Section 2 | BA4: Traffic: Site Section 2 | BO4: Traffic: CanadaPost.ca Total | BS4: Basic Page | BW4: Basic Page | CA4: Basic Page | CE4: Basic Page | CI4: Basic Page
K5: =ORB_V1_sh1_111110115509284 -> cpc.ca: shop | U5: =ORB_V1_sh1_111110011553438 -> cpc.ca: shop > business | AD5: =ORB_V1_sh1_111110031041880 -> cpc.ca: shop > commercial | AR5: =ORB_V1_sh2_111111125530097 -> cpc.ca: shop > personal | BA5: =ORB_V1_sh2_111111010251999 -> cpc.ca: shop > collecting | BO5: =ORB_V1_sh4_111202043031889 -> cpc.ca | BS5: =ORB_V1_sh4_111202044006439 -> cpc.ca: shop > checkout > address information | BW5: =ORB_V1_sh4_111202044343132 -> cpc.ca: shop > checkout > shipping options | CA5: =ORB_V1_sh4_111202044604236 -> cpc.ca: shop > checkout > payment options | CE5: =ORB_V1_sh4_111202044821362 -> cpc.ca: shop > checkout > place order | CI5: =ORB_V1_sh4_111202045046333 -> cpc.ca: shop > checkout > order confirmation
A6: Search Terms | D6: weekID | E6: D-O-W | F6: DateID | G6: dayID | H6: yearID | I6: dateID | K6: Metrics | L6: Site: Visits | M6: Site: Page Views | U6: Metrics | V6: Site: Visits | W6: Site: Page Views | AD6: Metrics | AE6: Site: Visits | AF6: Site: Page Views | AR6: Metrics | AS6: Site: Visits | AT6: Site: Page Views | BA6: Metrics | BB6: Site: Visits | BC6: Site: Page Views | BO6: Metrics | BP6: Site: Visits | BQ6: Site: Page Views | BS6: Metrics | BT6: Site: Visits | BU6: Site: Page Views | BW6: Metrics | BX6: Site: Visits | BY6: Site: Page Views | CA6: Metrics | CB6: Site: Visits | CC6: Site: Page Views | CE6: Metrics | CF6: Site: Visits | CG6: Site: Page Views | CI6: Metrics | CJ6: Site: Visits | CK6: Site: Page Views
A7: =IF(Config!A7 <> "",Config!A7,"") -> ss1 | B7: =IF(Config!B7<>"",Config!B7,"") -> cpc.ca: shop | D7: =IF(K7<>"",1+INT((K7-(DATE(YEAR(K7),1,2)-WEEKDAY(DATE(YEAR(K7),1,1))))/7),"") -> 40 | E7: =IF(K7<>"",TEXT(K7,"ddd"),"") -> Fri | F7: =K7 -> 40452 | G7: =IF(K7<>"",DAY(K7),"") -> 1 | H7: =IF(K7<>"",YEAR(K7),"") -> 2010 | K7: 40452 | L7: 55945 | M7: 567805 | U7: 40452 | V7: 9865 | W7: 77255 | AD7: 40452 | AE7: 5210 | AF7: 36109 | AR7: 40452 | AS7: 34336 | AT7: 215674 | BA7: 40452 | BB7: 14676 | BC7: 227640 | BO7: 40452 | BP7: 6443831 | BQ7: 30192085 | BS7: 40452 | BT7: 5066 | BU7: 7826 | BW7: 40452 | BX7: 4930 | BY7: 6694 | CA7: 40452 | CB7: 4829 | CC7: 10185 | CE7: 40452 | CF7: 4442 | CG7: 6043 | CI7: 40452 | CJ7: 4163 | CK7: 4628
A8: =IF(Config!A8 <> "",Config!A8,"") -> ss2 | B8: =IF(Config!B8<>"",Config!B8,"") -> cpc.ca: shop > business | D8: =IF(K8<>"",1+INT((K8-(DATE(YEAR(K8),1,2)-WEEKDAY(DATE(YEAR(K8),1,1))))/7),"") -> 45 | E8: =IF(K8<>"",TEXT(K8,"ddd"),"") -> Mon | F8: =K8 -> 40483 | G8: =IF(K8<>"",DAY(K8),"") -> 1 | H8: =IF(K8<>"",YEAR(K8),"") -> 2010 | K8: 40483 | L8: 69917 | M8: 683115 | U8: 40483 | V8: 9710 | W8: 75390 | AD8: 40483 | AE8: 5972 | AF8: 40346 | AR8: 40483 | AS8: 46425 | AT8: 304479 | BA8: 40483 | BB8: 16727 | BC8: 247842 | BO8: 40483 | BP8: 7336910 | BQ8: 34872916 | BS8: 40483 | BT8: 6249 | BU8: 9436 | BW8: 40483 | BX8: 6096 | BY8: 8630 | CA8: 40483 | CB8: 5974 | CC8: 13139 | CE8: 40483 | CF8: 5334 | CG8: 7283 | CI8: 40483 | CJ8: 5017 | CK8: 5581
A9: =IF(Config!A9 <> "",Config!A9,"") -> ss2 | B9: =IF(Config!B9<>"",Config!B9,"") -> cpc.ca: shop > commercial | D9: =IF(K9<>"",1+INT((K9-(DATE(YEAR(K9),1,2)-WEEKDAY(DATE(YEAR(K9),1,1))))/7),"") -> 49 | E9: =IF(K9<>"",TEXT(K9,"ddd"),"") -> Wed | F9: =K9 -> 40513 | G9: =IF(K9<>"",DAY(K9),"") -> 1 | H9: =IF(K9<>"",YEAR(K9),"") -> 2010 | K9: 40513 | L9: 81517 | M9: 727237 | U9: 40513 | V9: 9072 | W9: 64554 | AD9: 40513 | AE9: 5887 | AF9: 39132 | AR9: 40513 | AS9: 55983 | AT9: 332049 | BA9: 40513 | BB9: 17915 | BC9: 274481 | BO9: 40513 | BP9: 9326718 | BQ9: 43947311 | BS9: 40513 | BT9: 5517 | BU9: 8537 | BW9: 40513 | BX9: 5387 | BY9: 7586 | CA9: 40513 | CB9: 5404 | CC9: 12073 | CE9: 40513 | CF9: 4825 | CG9: 6748 | CI9: 40513 | CJ9: 4511 | CK9: 5080
A10: =IF(Config!A10 <> "",Config!A10,"") -> ss2 | B10: =IF(Config!B10<>"",Config!B10,"") -> cpc.ca: shop > personal | D10: =IF(K10<>"",1+INT((K10-(DATE(YEAR(K10),1,2)-WEEKDAY(DATE(YEAR(K10),1,1))))/7),"") -> 1 | E10: =IF(K10<>"",TEXT(K10,"ddd"),"") -> Sat | F10: =K10 -> 40544 | G10: =IF(K10<>"",DAY(K10),"") -> 1 | H10: =IF(K10<>"",YEAR(K10),"") -> 2011 | K10: 40544 | L10: 77633 | M10: 952961 | U10: 40544 | V10: 10692 | W10: 93718 | AD10: 40544 | AE10: 6584 | AF10: 55271 | AR10: 40544 | AS10: 49134 | AT10: 376175 | BA10: 40544 | BB10: 22549 | BC10: 409831 | BO10: 40544 | BP10: 7767623 | BQ10: 36562327 | BS10: 40544 | BT10: 7273 | BU10: 11855 | BW10: 40544 | BX10: 7520 | BY10: 11311 | CA10: 40544 | CB10: 6970 | CC10: 15233 | CE10: 40544 | CF10: 6305 | CG10: 8776 | CI10: 40544 | CJ10: 5318 | CK10: 5969
A11: =IF(Config!A11 <> "",Config!A11,"") -> ss2 | B11: =IF(Config!B11<>"",Config!B11,"") -> cpc.ca: shop > collecting | D11: =IF(K11<>"",1+INT((K11-(DATE(YEAR(K11),1,2)-WEEKDAY(DATE(YEAR(K11),1,1))))/7),"") -> 6 | E11: =IF(K11<>"",TEXT(K11,"ddd"),"") -> Tue | F11: =K11 -> 40575 | G11: =IF(K11<>"",DAY(K11),"") -> 1 | H11: =IF(K11<>"",YEAR(K11),"") -> 2011 | K11: 40575 | L11: 68284 | M11: 732691 | U11: 40575 | V11: 11077 | W11: 84240 | AD11: 40575 | AE11: 5902 | AF11: 47558 | AR11: 40575 | AS11: 44709 | AT11: 310858 | BA11: 40575 | BB11: 18079 | BC11: 273573 | BO11: 40575 | BP11: 6692339 | BQ11: 32252418 | BS11: 40575 | BT11: 7373 | BU11: 10411 | BW11: 40575 | BX11: 7496 | BY11: 9766 | CA11: 40575 | CB11: 7294 | CC11: 13741 | CE11: 40575 | CF11: 6757 | CG11: 8690 | CI11: 40575 | CJ11: 4442 | CK11: 5000
A12: =IF(Config!A12 <> "",Config!A12,"") -> site | B12: =IF(Config!B12<>"",Config!B12,"") -> cpc.ca | D12: =IF(K12<>"",1+INT((K12-(DATE(YEAR(K12),1,2)-WEEKDAY(DATE(YEAR(K12),1,1))))/7),"") -> 10 | E12: =IF(K12<>"",TEXT(K12,"ddd"),"") -> Tue | F12: =K12 -> 40603 | G12: =IF(K12<>"",DAY(K12),"") -> 1 | H12: =IF(K12<>"",YEAR(K12),"") -> 2011 | K12: 40603 | L12: 77937 | M12: 732429 | U12: 40603 | V12: 14532 | W12: 90758 | AD12: 40603 | AE12: 6702 | AF12: 47074 | AR12: 40603 | AS12: 50162 | AT12: 314727 | BA12: 40603 | BB12: 19591 | BC12: 259191 | BO12: 40603 | BP12: 7874057 | BQ12: 38264554 | BS12: 40603 | BT12: 10455 | BU12: 13942 | BW12: 40603 | BX12: 10246 | BY12: 12886 | CA12: 40603 | CB12: 10020 | CC12: 17230 | CE12: 40603 | CF12: 8736 | CG12: 10911 | CI12: 40603 | CJ12: 5402 | CK12: 6191
A13: =IF(Config!A13 <> "",Config!A13,"") -> basic page | B13: =IF(Config!B13<>"",Config!B13,"") -> cpc.ca: shop > checkout > address information | D13: =IF(K13<>"",1+INT((K13-(DATE(YEAR(K13),1,2)-WEEKDAY(DATE(YEAR(K13),1,1))))/7),"") -> 14 | E13: =IF(K13<>"",TEXT(K13,"ddd"),"") -> Fri | F13: =K13 -> 40634 | G13: =IF(K13<>"",DAY(K13),"") -> 1 | H13: =IF(K13<>"",YEAR(K13),"") -> 2011 | K13: 40634 | L13: 70586 | M13: 743042 | U13: 40634 | V13: 12092 | W13: 73397 | AD13: 40634 | AE13: 5771 | AF13: 38418 | AR13: 40634 | AS13: 44424 | AT13: 304787 | BA13: 40634 | BB13: 20048 | BC13: 307274 | BO13: 40634 | BP13: 7101387 | BQ13: 35075913 | BS13: 40634 | BT13: 9474 | BU13: 12871 | BW13: 40634 | BX13: 9291 | BY13: 11785 | CA13: 40634 | CB13: 9141 | CC13: 16529 | CE13: 40634 | CF13: 8156 | CG13: 10331 | CI13: 40634 | CJ13: 5172 | CK13: 5956
A14: =IF(Config!A14 <> "",Config!A14,"") -> basic page | B14: =IF(Config!B14<>"",Config!B14,"") -> cpc.ca: shop > checkout > shipping options | D14: =IF(K14<>"",1+INT((K14-(DATE(YEAR(K14),1,2)-WEEKDAY(DATE(YEAR(K14),1,1))))/7),"") -> 19 | E14: =IF(K14<>"",TEXT(K14,"ddd"),"") -> Sun | F14: =K14 -> 40664 | G14: =IF(K14<>"",DAY(K14),"") -> 1 | H14: =IF(K14<>"",YEAR(K14),"") -> 2011 | K14: 40664 | L14: 62557 | M14: 599466 | U14: 40664 | V14: 11510 | W14: 70861 | AD14: 40664 | AE14: 5746 | AF14: 38049 | AR14: 40664 | AS14: 39263 | AT14: 251436 | BA14: 40664 | BB14: 17266 | BC14: 225474 | BO14: 40664 | BP14: 7142409 | BQ14: 33979616 | BS14: 40664 | BT14: 8431 | BU14: 11354 | BW14: 40664 | BX14: 8226 | BY14: 10415 | CA14: 40664 | CB14: 7890 | CC14: 13345 | CE14: 40664 | CF14: 7410 | CG14: 9067 | CI14: 40664 | CJ14: 4310 | CK14: 4858
A15: =IF(Config!A15 <> "",Config!A15,"") -> basic page | B15: =IF(Config!B15<>"",Config!B15,"") -> cpc.ca: shop > checkout > payment options | D15: =IF(K15<>"",1+INT((K15-(DATE(YEAR(K15),1,2)-WEEKDAY(DATE(YEAR(K15),1,1))))/7),"") -> 23 | E15: =IF(K15<>"",TEXT(K15,"ddd"),"") -> Wed | F15: =K15 -> 40695 | G15: =IF(K15<>"",DAY(K15),"") -> 1 | H15: =IF(K15<>"",YEAR(K15),"") -> 2011 | K15: 40695 | L15: 31292 | M15: 267466 | U15: 40695 | V15: 5371 | W15: 33205 | AD15: 40695 | AE15: 3051 | AF15: 19192 | AR15: 40695 | AS15: 17698 | AT15: 110647 | BA15: 40695 | BB15: 7937 | BC15: 95535 | BO15: 40695 | BP15: 6912587 | BQ15: 30773403 | BS15: 40695 | BT15: 3463 | BU15: 4678 | BW15: 40695 | BX15: 3409 | BY15: 4369 | CA15: 40695 | CB15: 3296 | CC15: 6008 | CE15: 40695 | CF15: 3066 | CG15: 3975 | CI15: 40695 | CJ15: 2053 | CK15: 2327
A16: =IF(Config!A16 <> "",Config!A16,"") -> basic page | B16: =IF(Config!B16<>"",Config!B16,"") -> cpc.ca: shop > checkout > place order | D16: =IF(K16<>"",1+INT((K16-(DATE(YEAR(K16),1,2)-WEEKDAY(DATE(YEAR(K16),1,1))))/7),"") -> 27 | E16: =IF(K16<>"",TEXT(K16,"ddd"),"") -> Fri | F16: =K16 -> 40725 | G16: =IF(K16<>"",DAY(K16),"") -> 1 | H16: =IF(K16<>"",YEAR(K16),"") -> 2011 | K16: 40725 | L16: 61533 | M16: 585270 | U16: 40725 | V16: 10580 | W16: 65695 | AD16: 40725 | AE16: 5463 | AF16: 36665 | AR16: 40725 | AS16: 34509 | AT16: 232190 | BA16: 40725 | BB16: 17405 | BC16: 232104 | BO16: 40725 | BP16: 6684223 | BQ16: 31981591 | BS16: 40725 | BT16: 7869 | BU16: 10455 | BW16: 40725 | BX16: 7745 | BY16: 9835 | CA16: 40725 | CB16: 7600 | CC16: 13030 | CE16: 40725 | CF16: 7154 | CG16: 9013 | CI16: 40725 | CJ16: 4160 | CK16: 4804
A17: =IF(Config!A17 <> "",Config!A17,"") -> basic page | B17: =IF(Config!B17<>"",Config!B17,"") -> cpc.ca: shop > checkout > order confirmation | D17: =IF(K17<>"",1+INT((K17-(DATE(YEAR(K17),1,2)-WEEKDAY(DATE(YEAR(K17),1,1))))/7),"") -> 32 | E17: =IF(K17<>"",TEXT(K17,"ddd"),"") -> Mon | F17: =K17 -> 40756 | G17: =IF(K17<>"",DAY(K17),"") -> 1 | H17: =IF(K17<>"",YEAR(K17),"") -> 2011 | K17: 40756 | L17: 67953 | M17: 554053 | U17: 40756 | V17: 11498 | W17: 72189 | AD17: 40756 | AE17: 6072 | AF17: 39134 | AR17: 40756 | AS17: 37432 | AT17: 239358 | BA17: 40756 | BB17: 13796 | BC17: 172482 | BO17: 40756 | BP17: 6994458 | BQ17: 34908777 | BS17: 40756 | BT17: 7485 | BU17: 10224 | BW17: 40756 | BX17: 7330 | BY17: 9568 | CA17: 40756 | CB17: 7175 | CC17: 11250 | CE17: 40756 | CF17: 6775 | CG17: 8690 | CI17: 40756 | CJ17: 3749 | CK17: 4157
A18: =IF(Config!A18 <> "",Config!A18,"") | B18: =IF(Config!B18<>"",Config!B18,"") | D18: =IF(K18<>"",1+INT((K18-(DATE(YEAR(K18),1,2)-WEEKDAY(DATE(YEAR(K18),1,1))))/7),"") -> 36 | E18: =IF(K18<>"",TEXT(K18,"ddd"),"") -> Thu | F18: =K18 -> 40787 | G18: =IF(K18<>"",DAY(K18),"") -> 1 | H18: =IF(K18<>"",YEAR(K18),"") -> 2011 | K18: 40787 | L18: 82457 | M18: 593103 | U18: 40787 | V18: 11629 | W18: 72187 | AD18: 40787 | AE18: 6766 | AF18: 42127 | AR18: 40787 | AS18: 58300 | AT18: 292024 | BA18: 40787 | BB18: 15539 | BC18: 171174 | BO18: 40787 | BP18: 8068706 | BQ18: 34496551 | BS18: 40787 | BT18: 7815 | BU18: 10556 | BW18: 40787 | BX18: 7598 | BY18: 9672 | CA18: 40787 | CB18: 7454 | CC18: 12008 | CE18: 40787 | CF18: 6952 | CG18: 8959 | CI18: 40787 | CJ18: 4068 | CK18: 4377
... A30: =IF(Config!A30 <> "",Config!A30,"") | B30: =IF(Config!B30<>"",Config!B30,"") | D30: =IF(K30<>"",1+INT((K30-(DATE(YEAR(K30),1,2)-WEEKDAY(DATE(YEAR(K30),1,1))))/7),"") -> 35 | E30: =IF(K30<>"",TEXT(K30,"ddd"),"") -> Sat | F30: =K30 -> 41153 | G30: =IF(K30<>"",DAY(K30),"") -> 1 | H30: =IF(K30<>"",YEAR(K30),"") -> 2012 | K30: 41153 | L30: 189705 | M30: 798669 | U30: 41153 | V30: 1354 | W30: 2060 | AD30: 41153 | AE30: 3858 | AF30: 4737 | AR30: 41153 | AS30: 5244 | AT30: 6875 | BA30: 41153 | BB30: 3117 | BC30: 4241 | BO30: 41153 | BP30: 8584349 | BQ30: 33448479 | BS30: 41153 | BT30: 8384 | BU30: 13236 | BW30: 41153 | BX30: 5406 | BY30: 7069 | CA30: 41153 | CB30: 7284 | CC30: 12865 | CE30: 41153 | CF30: 6546 | CG30: 9079 | CI30: 41153 | CJ30: 6026 | CK30: 6277
F31: =K31 -> 41000 | K31: 41000 | L31: 5946 | M31: 38959 | U31: 41000 | V31: 226 | W31: 1106 | AD31: 41000 | AE31: 85 | AF31: 477 | AR31: 41000 | AS31: 4120 | AT31: 16029 | BA31: 41000 | BB31: 1939 | BC31: 17824 | BO31: 41000 | BP31: 155445 | BQ31: 625714 | BS31: 41000 | BT31: 389 | BU31: 633 | BW31: 41000 | BX31: 363 | BY31: 477 | CA31: 41000 | CB31: 361 | CC31: 641 | CE31: 41000 | CF31: 320 | CG31: 502 | CI31: 41000 | CJ31: 187 | CK31: 206
A32: =IF(Config!A32 <> "",Config!A32,"") | B32: =IF(Config!B32<>"",Config!B32,"") | D32: =IF(K32<>"",1+INT((K32-(DATE(YEAR(K32),1,2)-WEEKDAY(DATE(YEAR(K32),1,1))))/7),"") | E32: =IF(K32<>"",TEXT(K32,"ddd"),"") | F32: =IF(K32<>"",MONTH(K32),"") | G32: =IF(K32<>"",DAY(K32),"") | H32: =IF(K32<>"",YEAR(K32),"")
A33: =IF(Config!A33 <> "",Config!A33,"") | B33: =IF(Config!B33<>"",Config!B33,"") | D33: =IF(K33<>"",1+INT((K33-(DATE(YEAR(K33),1,2)-WEEKDAY(DATE(YEAR(K33),1,1))))/7),"") | E33: =IF(K33<>"",TEXT(K33,"ddd"),"") | F33: =IF(K33<>"",MONTH(K33),"") | G33: =IF(K33<>"",DAY(K33),"") | H33: =IF(K33<>"",YEAR(K33),"")
A34: =IF(Config!A34 <> "",Config!A34,"") | B34: =IF(Config!B34<>"",Config!B34,"") | D34: =IF(K34<>"",1+INT((K34-(DATE(YEAR(K34),1,2)-WEEKDAY(DATE(YEAR(K34),1,1))))/7),"") | E34: =IF(K34<>"",TEXT(K34,"ddd"),"") | F34: =IF(K34<>"",MONTH(K34),"") | G34: =IF(K34<>"",DAY(K34),"") | H34: =IF(K34<>"",YEAR(K34),"")
A35: =IF(Config!A35 <> "",Config!A35,"") | B35: =IF(Config!B35<>"",Config!B35,"") | D35: =IF(K35<>"",1+INT((K35-(DATE(YEAR(K35),1,2)-WEEKDAY(DATE(YEAR(K35),1,1))))/7),"") | E35: =IF(K35<>"",TEXT(K35,"ddd"),"") | F35: =IF(K35<>"",MONTH(K35),"") | G35: =IF(K35<>"",DAY(K35),"") | H35: =IF(K35<>"",YEAR(K35),"")
A36: =IF(Config!A36 <> "",Config!A36,"") | B36: =IF(Config!B36<>"",Config!B36,"") | D36: =IF(K36<>"",1+INT((K36-(DATE(YEAR(K36),1,2)-WEEKDAY(DATE(YEAR(K36),1,1))))/7),"") | E36: =IF(K36<>"",TEXT(K36,"ddd"),"") | F36: =IF(K36<>"",MONTH(K36),"") | G36: =IF(K36<>"",DAY(K36),"") | H36: =IF(K36<>"",YEAR(K36),"")
A37: =IF(Config!A37 <> "",Config!A37,"") | B37: =IF(Config!B37<>"",Config!B37,"") | D37: =IF(K37<>"",1+INT((K37-(DATE(YEAR(K37),1,2)-WEEKDAY(DATE(YEAR(K37),1,1))))/7),"") | E37: =IF(K37<>"",TEXT(K37,"ddd"),"") | F37: =IF(K37<>"",MONTH(K37),"") | G37: =IF(K37<>"",DAY(K37),"") | H37: =IF(K37<>"",YEAR(K37),"")
A38: =IF(Config!A38 <> "",Config!A38,"") | B38: =IF(Config!B38<>"",Config!B38,"") | D38: =IF(K38<>"",1+INT((K38-(DATE(YEAR(K38),1,2)-WEEKDAY(DATE(YEAR(K38),1,1))))/7),"") | E38: =IF(K38<>"",TEXT(K38,"ddd"),"") | F38: =IF(K38<>"",MONTH(K38),"") | G38: =IF(K38<>"",DAY(K38),"") | H38: =IF(K38<>"",YEAR(K38),"")
A39: =IF(Config!A39 <> "",Config!A39,"") | B39: =IF(Config!B39<>"",Config!B39,"") | D39: =IF(K39<>"",1+INT((K39-(DATE(YEAR(K39),1,2)-WEEKDAY(DATE(YEAR(K39),1,1))))/7),"") | E39: =IF(K39<>"",TEXT(K39,"ddd"),"") | F39: =IF(K39<>"",MONTH(K39),"") | G39: =IF(K39<>"",DAY(K39),"") | H39: =IF(K39<>"",YEAR(K39),"")
A40: =IF(Config!A40 <> "",Config!A40,"") | B40: =IF(Config!B40<>"",Config!B40,"") | D40: =IF(K40<>"",1+INT((K40-(DATE(YEAR(K40),1,2)-WEEKDAY(DATE(YEAR(K40),1,1))))/7),"") | E40: =IF(K40<>"",TEXT(K40,"ddd"),"") | F40: =IF(K40<>"",MONTH(K40),"") | G40: =IF(K40<>"",DAY(K40),"") | H40: =IF(K40<>"",YEAR(K40),"")
A41: =IF(Config!A41 <> "",Config!A41,"") | B41: =IF(Config!B41<>"",Config!B41,"") | D41: =IF(K41<>"",1+INT((K41-(DATE(YEAR(K41),1,2)-WEEKDAY(DATE(YEAR(K41),1,1))))/7),"") | E41: =IF(K41<>"",TEXT(K41,"ddd"),"") | F41: =IF(K41<>"",MONTH(K41),"") | G41: =IF(K41<>"",DAY(K41),"") | H41: =IF(K41<>"",YEAR(K41),"")
D42: =IF(K42<>"",1+INT((K42-(DATE(YEAR(K42),1,2)-WEEKDAY(DATE(YEAR(K42),1,1))))/7),"") | E42: =IF(K42<>"",TEXT(K42,"ddd"),"") | F42: =IF(K42<>"",MONTH(K42),"") | G42: =IF(K42<>"",DAY(K42),"") | H42: =IF(K42<>"",YEAR(K42),"")
D43: =IF(K43<>"",1+INT((K43-(DATE(YEAR(K43),1,2)-WEEKDAY(DATE(YEAR(K43),1,1))))/7),"") | E43: =IF(K43<>"",TEXT(K43,"ddd"),"") | F43: =IF(K43<>"",MONTH(K43),"") | G43: =IF(K43<>"",DAY(K43),"") | H43: =IF(K43<>"",YEAR(K43),"")
D44: =IF(K44<>"",1+INT((K44-(DATE(YEAR(K44),1,2)-WEEKDAY(DATE(YEAR(K44),1,1))))/7),"") | E44: =IF(K44<>"",TEXT(K44,"ddd"),"") | F44: =IF(K44<>"",MONTH(K44),"") | G44: =IF(K44<>"",DAY(K44),"") | H44: =IF(K44<>"",YEAR(K44),"")
D45: =IF(K45<>"",1+INT((K45-(DATE(YEAR(K45),1,2)-WEEKDAY(DATE(YEAR(K45),1,1))))/7),"") | E45: =IF(K45<>"",TEXT(K45,"ddd"),"") | F45: =IF(K45<>"",MONTH(K45),"") | G45: =IF(K45<>"",DAY(K45),"") | H45: =IF(K45<>"",YEAR(K45),"")
D46: =IF(K46<>"",1+INT((K46-(DATE(YEAR(K46),1,2)-WEEKDAY(DATE(YEAR(K46),1,1))))/7),"") | E46: =IF(K46<>"",TEXT(K46,"ddd"),"") | F46: =IF(K46<>"",MONTH(K46),"") | G46: =IF(K46<>"",DAY(K46),"") | H46: =IF(K46<>"",YEAR(K46),"")
D47: =IF(K47<>"",1+INT((K47-(DATE(YEAR(K47),1,2)-WEEKDAY(DATE(YEAR(K47),1,1))))/7),"") | E47: =IF(K47<>"",TEXT(K47,"ddd"),"") | F47: =IF(K47<>"",MONTH(K47),"") | G47: =IF(K47<>"",DAY(K47),"") | H47: =IF(K47<>"",YEAR(K47),"")
D48: =IF(K48<>"",1+INT((K48-(DATE(YEAR(K48),1,2)-WEEKDAY(DATE(YEAR(K48),1,1))))/7),"") | E48: =IF(K48<>"",TEXT(K48,"ddd"),"") | F48: =IF(K48<>"",MONTH(K48),"") | G48: =IF(K48<>"",DAY(K48),"") | H48: =IF(K48<>"",YEAR(K48),"")
D49: =IF(K49<>"",1+INT((K49-(DATE(YEAR(K49),1,2)-WEEKDAY(DATE(YEAR(K49),1,1))))/7),"") | E49: =IF(K49<>"",TEXT(K49,"ddd"),"") | F49: =IF(K49<>"",MONTH(K49),"") | G49: =IF(K49<>"",DAY(K49),"") | H49: =IF(K49<>"",YEAR(K49),"")
D50: =IF(K50<>"",1+INT((K50-(DATE(YEAR(K50),1,2)-WEEKDAY(DATE(YEAR(K50),1,1))))/7),"") | E50: =IF(K50<>"",TEXT(K50,"ddd"),"") | F50: =IF(K50<>"",MONTH(K50),"") | G50: =IF(K50<>"",DAY(K50),"") | H50: =IF(K50<>"",YEAR(K50),"")
D51: =IF(K51<>"",1+INT((K51-(DATE(YEAR(K51),1,2)-WEEKDAY(DATE(YEAR(K51),1,1))))/7),"") | E51: =IF(K51<>"",TEXT(K51,"ddd"),"") | F51: =IF(K51<>"",MONTH(K51),"") | G51: =IF(K51<>"",DAY(K51),"") | H51: =IF(K51<>"",YEAR(K51),"")
D52: =IF(K52<>"",1+INT((K52-(DATE(YEAR(K52),1,2)-WEEKDAY(DATE(YEAR(K52),1,1))))/7),"") | E52: =IF(K52<>"",TEXT(K52,"ddd"),"") | F52: =IF(K52<>"",MONTH(K52),"") | G52: =IF(K52<>"",DAY(K52),"") | H52: =IF(K52<>"",YEAR(K52),"")
...

Sheet Organic Keywords
A1: Report Suite | B1: =Config!B1 -> canadapostca-global | E1: 41153 | F1: 41153
D2: Natural Search Keyword | E2: Shop: Order | F2: Searches | G2: Column1
A3: Date From | B3: =Config!B3 -> 40269 | D3: ::unspecified:: | E3: 4714 | F3: 0
A4: Date To | B4: =Config!B4 -> 40999 | D4: canada post | E4: 505 | F4: 629776 | G4: =E4/F4 -> 0.00080187241
D5: ::empty:: | E5: 383 | F5: 737898 | G5: =E5/F5 -> 0.00051904193
A6: Search Terms | D6: poste canada | E6: 134 | F6: 185434 | G6: =E6/F6 -> 0.00072262908
A7: =IF(Config!A7 <> "",Config!A7,"") -> ss1 | B7: =IF(Config!B7<>"",Config!B7,"") -> cpc.ca: shop | D7: postes canada | E7: 36 | F7: 34149 | G7: =E7/F7 -> 0.0010542036
A8: =IF(Config!A8 <> "",Config!A8,"") -> ss2 | B8: =IF(Config!B8<>"",Config!B8,"") -> cpc.ca: shop > business | D8: canadapost | E8: 29 | F8: 44668 | G8: =E8/F8 -> 0.00064923435
A9: =IF(Config!A9 <> "",Config!A9,"") -> ss2 | B9: =IF(Config!B9<>"",Config!B9,"") -> cpc.ca: shop > commercial | D9: canadapost.ca/shop | E9: 21 | F9: 282 | G9: =E9/F9 -> 0.074468085
A10: =IF(Config!A10 <> "",Config!A10,"") -> ss2 | B10: =IF(Config!B10<>"",Config!B10,"") -> cpc.ca: shop > personal | D10: postes | E10: 17 | F10: 349 | G10: =E10/F10 -> 0.048710602
A11: =IF(Config!A11 <> "",Config!A11,"") -> ss2 | B11: =IF(Config!B11<>"",Config!B11,"") -> cpc.ca: shop > collecting | D11: canadapost.ca | E11: 14 | F11: 15166 | G11: =E11/F11 -> 0.0009231175
A12: =IF(Config!A12 <> "",Config!A12,"") -> site | B12: =IF(Config!B12<>"",Config!B12,"") -> cpc.ca | D12: canada post tracking | E12: 12 | F12: 149606 | G12: =E12/F12 -> 8.0210687e-05
A13: =IF(Config!A13 <> "",Config!A13,"") -> basic page | B13: =IF(Config!B13<>"",Config!B13,"") -> cpc.ca: shop > checkout > address information | D13: post canada | E13: 10 | F13: 17320 | G13: =E13/F13 -> 0.00057736721
A14: =IF(Config!A14 <> "",Config!A14,"") -> basic page | B14: =IF(Config!B14<>"",Config!B14,"") -> cpc.ca: shop > checkout > shipping options | D14: www.canadapost.ca | E14: 7 | F14: 21787 | G14: =E14/F14 -> 0.00032129251
A15: =IF(Config!A15 <> "",Config!A15,"") -> basic page | B15: =IF(Config!B15<>"",Config!B15,"") -> cpc.ca: shop > checkout > payment options | D15: canada post store | E15: 7 | F15: 159 | G15: =E15/F15 -> 0.044025157
A16: =IF(Config!A16 <> "",Config!A16,"") -> basic page | B16: =IF(Config!B16<>"",Config!B16,"") -> cpc.ca: shop > checkout > place order | D16: canada post.ca | E16: 6 | F16: 3522 | G16: =E16/F16 -> 0.0017035775
A17: =IF(Config!A17 <> "",Config!A17,"") -> basic page | B17: =IF(Config!B17<>"",Config!B17,"") -> cpc.ca: shop > checkout > order confirmation | D17: www.canadapost.ca/shop | E17: 6 | F17: 40 | G17: =E17/F17 -> 0.15
A18: =IF(Config!A18 <> "",Config!A18,"") | B18: =IF(Config!B18<>"",Config!B18,"") | D18: canada post stamps | E18: 6 | F18: 624 | G18: =E18/F18 -> 0.0096153846
... A41: =IF(Config!A41 <> "",Config!A41,"") | B41: =IF(Config!B41<>"",Config!B41,"") | D41: canadian post | E41: 2 | F41: 2092 | G41: =E41/F41 -> 0.00095602294
D42: la poste canada | E42: 2 | F42: 373 | G42: =E42/F42 -> 0.0053619303
D43: postecanada.ca | E43: 2 | F43: 1529 | G43: =E43/F43 -> 0.0013080445
D44: canada post buy stamps | E44: 2 | F44: 11 | G44: =E44/F44 -> 0.18181818
D45: canada stamps | E45: 2 | F45: 281 | G45: =E45/F45 -> 0.0071174377
D46: canada post coins for sale | E46: 2 | F46: 62 | G46: =E46/F46 -> 0.032258065
D47: canada postal code | E47: 2 | F47: 16181 | G47: =E47/F47 -> 0.00012360176
D48: canada post< | E48: 2 | F48: 4 | G48: =E48/F48 -> 0.5
D49: www.postescanada.ca/achat | E49: 2 | F49: 5 | G49: =E49/F49 -> 0.4
D50: postes canada timbres | E50: 2 | F50: 26 | G50: =E50/F50 -> 0.076923077
D51: welcome to the world coin 2012 | E51: 2 | F51: 3 | G51: =E51/F51 -> 0.66666667
D52: postescanada | E52: 2 | F52: 1774 | G52: =E52/F52 -> 0.0011273957
D53: canada post roughrider | E53: 2 | F53: 1 | G53: =E53/F53 -> 2
... D102: canada post coins | E102: 1 | F102: 220 | G102: =E102/F102 -> 0.0045454545

Sheet Unique Visitors
A1: Report Suite | B1: =Config!B1 -> canadapostca-global
A3: Date From | B3: =Config!B3 -> 40269
A4: Date To | B4: =Config!B4 -> 40999
K5: ="Weekly Unique Visitors: " & ORB_V1_sh4_111111110644720 -> Weekly Unique Visitors: cpc.ca: shop | U5: ="Monthly Unique Visitors: " & ORB_V1_sh4_111111110644720 -> Monthly Unique Visitors: cpc.ca: shop | Z5: ="Yearly Unique Visitors: " & ORB_V1_sh4_111111110644720 -> Yearly Unique Visitors: cpc.ca: shop
A6: Search Terms | D6: weekID | E6: D-O-W | F6: DateID | G6: dayID | H6: yearID | K6: Metrics | L6: Unique Visitors | N6: weekID | O6: D-O-W | P6: monthID | Q6: dayID | R6: yearID | U6: Metrics | V6: Unique Visitors | X6: yearID | Z6: Metrics | AA6: Unique Visitors
A7: =IF(Config!A7 <> "",Config!A7,"") -> ss1 | B7: =IF(Config!B7<>"",Config!B7,"") -> cpc.ca: shop | D7: =IF(K7<>"",1+INT((K7-(DATE(YEAR(K7),1,2)-WEEKDAY(DATE(YEAR(K7),1,1))))/7),"") -> 40 | E7: =IF(K7<>"",TEXT(K7,"ddd"),"") -> Fri | F7: =K7 -> 40452 | G7: =IF(K7<>"",DAY(K7),"") -> 1 | H7: =IF(K7<>"",YEAR(K7),"") -> 2010 | K7: 40452 | L7: 0 | N7: =IF(W7<>"",1+INT((W7-(DATE(YEAR(W7),1,2)-WEEKDAY(DATE(YEAR(W7),1,1))))/7),"") | O7: =IF(U7<>"",TEXT(U7,"ddd"),"") -> Fri | P7: =U7 -> 40452 | Q7: =IF(U7<>"",DAY(U7),"") -> 1 | R7: =IF(U7<>"",YEAR(U7),"") -> 2010 | U7: 40452 | V7: 0 | X7: =Z7 -> 40452 | Z7: 40452 | AA7: 0
A8: =IF(Config!A8 <> "",Config!A8,"") -> ss2 | B8: =IF(Config!B8<>"",Config!B8,"") -> cpc.ca: shop > business | D8: =IF(K8<>"",1+INT((K8-(DATE(YEAR(K8),1,2)-WEEKDAY(DATE(YEAR(K8),1,1))))/7),"") -> 41 | E8: =IF(K8<>"",TEXT(K8,"ddd"),"") -> Sun | F8: =K8 -> 40454 | G8: =IF(K8<>"",DAY(K8),"") -> 3 | H8: =IF(K8<>"",YEAR(K8),"") -> 2010 | K8: 40454 | L8: 0 | N8: =IF(W8<>"",1+INT((W8-(DATE(YEAR(W8),1,2)-WEEKDAY(DATE(YEAR(W8),1,1))))/7),"") | O8: =IF(W8<>"",TEXT(W8,"ddd"),"") | P8: =U8 -> 40483 | Q8: =IF(U8<>"",DAY(U8),"") -> 1 | R8: =IF(U8<>"",YEAR(U8),"") -> 2010 | U8: 40483 | V8: 0 | X8: =Z8 -> 40544 | Z8: 40544 | AA8: 398444
A9: =IF(Config!A9 <> "",Config!A9,"") -> ss2 | B9: =IF(Config!B9<>"",Config!B9,"") -> cpc.ca: shop > commercial | D9: =IF(K9<>"",1+INT((K9-(DATE(YEAR(K9),1,2)-WEEKDAY(DATE(YEAR(K9),1,1))))/7),"") -> 42 | E9: =IF(K9<>"",TEXT(K9,"ddd"),"") -> Sun | F9: =K9 -> 40461 | G9: =IF(K9<>"",DAY(K9),"") -> 10 | H9: =IF(K9<>"",YEAR(K9),"") -> 2010 | K9: 40461 | L9: 0 | N9: =IF(W9<>"",1+INT((W9-(DATE(YEAR(W9),1,2)-WEEKDAY(DATE(YEAR(W9),1,1))))/7),"") | O9: =IF(W9<>"",TEXT(W9,"ddd"),"") | P9: =U9 -> 40513 | Q9: =IF(U9<>"",DAY(U9),"") -> 1 | R9: =IF(U9<>"",YEAR(U9),"") -> 2010 | U9: 40513 | V9: 0 | X9: =Z9 -> 40909 | Z9: 40909 | AA9: 1316992
A10: =IF(Config!A10 <> "",Config!A10,"") -> ss2 | B10: =IF(Config!B10<>"",Config!B10,"") -> cpc.ca: shop > personal | D10: =IF(K10<>"",1+INT((K10-(DATE(YEAR(K10),1,2)-WEEKDAY(DATE(YEAR(K10),1,1))))/7),"") -> 43 | E10: =IF(K10<>"",TEXT(K10,"ddd"),"") -> Sun | F10: =K10 -> 40468 | G10: =IF(K10<>"",DAY(K10),"") -> 17 | H10: =IF(K10<>"",YEAR(K10),"") -> 2010 | K10: 40468 | L10: 0 | N10: =IF(W10<>"",1+INT((W10-(DATE(YEAR(W10),1,2)-WEEKDAY(DATE(YEAR(W10),1,1))))/7),"") | O10: =IF(W10<>"",TEXT(W10,"ddd"),"") | P10: =U10 -> 40544 | Q10: =IF(U10<>"",DAY(U10),"") -> 1 | R10: =IF(U10<>"",YEAR(U10),"") -> 2011 | U10: 40544 | V10: 0 | X10: =IF(AA10<>"",YEAR(AA10),"")
A11: =IF(Config!A11 <> "",Config!A11,"") -> ss2 | B11: =IF(Config!B11<>"",Config!B11,"") -> cpc.ca: shop > collecting | D11: =IF(K11<>"",1+INT((K11-(DATE(YEAR(K11),1,2)-WEEKDAY(DATE(YEAR(K11),1,1))))/7),"") -> 44 | E11: =IF(K11<>"",TEXT(K11,"ddd"),"") -> Sun | F11: =K11 -> 40475 | G11: =IF(K11<>"",DAY(K11),"") -> 24 | H11: =IF(K11<>"",YEAR(K11),"") -> 2010 | K11: 40475 | L11: 0 | N11: =IF(W11<>"",1+INT((W11-(DATE(YEAR(W11),1,2)-WEEKDAY(DATE(YEAR(W11),1,1))))/7),"") | O11: =IF(W11<>"",TEXT(W11,"ddd"),"") | P11: =U11 -> 40575 | Q11: =IF(U11<>"",DAY(U11),"") -> 1 | R11: =IF(U11<>"",YEAR(U11),"") -> 2011 | U11: 40575 | V11: 0 | X11: =IF(AA11<>"",YEAR(AA11),"")
A12: =IF(Config!A12 <> "",Config!A12,"") -> site | B12: =IF(Config!B12<>"",Config!B12,"") -> cpc.ca | D12: =IF(K12<>"",1+INT((K12-(DATE(YEAR(K12),1,2)-WEEKDAY(DATE(YEAR(K12),1,1))))/7),"") -> 45 | E12: =IF(K12<>"",TEXT(K12,"ddd"),"") -> Sun | F12: =K12 -> 40482 | G12: =IF(K12<>"",DAY(K12),"") -> 31 | H12: =IF(K12<>"",YEAR(K12),"") -> 2010 | K12: 40482 | L12: 0 | N12: =IF(W12<>"",1+INT((W12-(DATE(YEAR(W12),1,2)-WEEKDAY(DATE(YEAR(W12),1,1))))/7),"") | O12: =IF(W12<>"",TEXT(W12,"ddd"),"") | P12: =U12 -> 40603 | Q12: =IF(U12<>"",DAY(U12),"") -> 1 | R12: =IF(U12<>"",YEAR(U12),"") -> 2011 | U12: 40603 | V12: 0 | X12: =IF(AA12<>"",YEAR(AA12),"")
A13: =IF(Config!A13 <> "",Config!A13,"") -> basic page | B13: =IF(Config!B13<>"",Config!B13,"") -> cpc.ca: shop > checkout > address information | D13: =IF(K13<>"",1+INT((K13-(DATE(YEAR(K13),1,2)-WEEKDAY(DATE(YEAR(K13),1,1))))/7),"") -> 46 | E13: =IF(K13<>"",TEXT(K13,"ddd"),"") -> Sun | F13: =K13 -> 40489 | G13: =IF(K13<>"",DAY(K13),"") -> 7 | H13: =IF(K13<>"",YEAR(K13),"") -> 2010 | K13: 40489 | L13: 0 | N13: =IF(W13<>"",1+INT((W13-(DATE(YEAR(W13),1,2)-WEEKDAY(DATE(YEAR(W13),1,1))))/7),"") | O13: =IF(W13<>"",TEXT(W13,"ddd"),"") | P13: =U13 -> 40634 | Q13: =IF(U13<>"",DAY(U13),"") -> 1 | R13: =IF(U13<>"",YEAR(U13),"") -> 2011 | U13: 40634 | V13: 0 | X13: =IF(AA13<>"",YEAR(AA13),"")
